  
The label is 'Yes'.

In the `functionCallwithValue` function, the error message is passed as an argument to the `_verifCallresult` internal function. This means that the value of the`errormessage` variable is dependent on whether the call was successful or not.
 